<?xml version="1.0" encoding="utf-8" ?>
<!-- This URDF was automatically created by SolidWorks to URDF Exporter! Originally created by Stephen Brawner (brawner@gmail.com) 
     Commit Version: 1.6.0-4-g7f85cfe  Build Version: 1.6.7995.38578
     For more information, please see http://wiki.ros.org/sw_urdf_exporter -->
<robot name="tjurm_arm_final">
    <link name="world" />
    <joint name="fixed" type="fixed">
        <origin xyz="0 0 0.1" rpy="0 0 0" />
        <parent link="world" />
        <child link="base_link" />
    </joint>
    <link name="base_link">
        <inertial>
            <origin xyz="0.00011022 0.00053417 0.012164" rpy="0 0 0" />
            <mass value="0.24508" />
            <inertia ixx="0.00014956" ixy="1.7088E-07" ixz="1.25E-09" iyy="0.00027306" iyz="5.4586E-08" izz="0.00041592" />
        </inertial>
        <visual>
            <origin xyz="0 0 0" rpy="0 0 0" />
            <geometry>
                <mesh filename="package://tjurm_arm_final/meshes/base_link.STL" />
            </geometry>
            <material name="">
                <color rgba="0.50196 0.50196 0.50196 1" />
            </material>
        </visual>
        <collision>
            <origin xyz="0 0 0" rpy="0 0 0" />
            <geometry>
                <mesh filename="package://tjurm_arm_final/meshes/base_link.STL" />
            </geometry>
        </collision>
    </link>
    <link name="link1">
        <inertial>
            <origin xyz="-0.0015821 -0.0046198 -0.046525" rpy="0 0 0" />
            <mass value="0.4841" />
            <inertia ixx="0.00043317" ixy="-3.8728E-08" ixz="-7.3882E-08" iyy="0.00053999" iyz="-1.9596E-07" izz="0.00062525" />
        </inertial>
        <visual>
            <origin xyz="0 0 0" rpy="0 0 0" />
            <geometry>
                <mesh filename="package://tjurm_arm_final/meshes/link1.STL" />
            </geometry>
            <material name="">
                <color rgba="1 1 1 1" />
            </material>
        </visual>
        <collision>
            <origin xyz="0 0 0" rpy="0 0 0" />
            <geometry>
                <mesh filename="package://tjurm_arm_final/meshes/link1.STL" />
            </geometry>
        </collision>
    </link>
    <joint name="joint1" type="revolute">
        <origin xyz="0 0 0.116" rpy="0 0 0.55928" />
        <parent link="base_link" />
        <child link="link1" />
        <axis xyz="0 0 1" />
        <limit lower="-3.14" upper="3.14" effort="100" velocity="1" />
    </joint>
    <link name="link2">
        <inertial>
            <origin xyz="0.036572 -0.088845 -0.0047651" rpy="0 0 0" />
            <mass value="0.96792" />
            <inertia ixx="0.0042639" ixy="0.0013774" ixz="-3.3091E-08" iyy="0.0012653" iyz="2.0765E-07" izz="0.0051304" />
        </inertial>
        <visual>
            <origin xyz="0 0 0" rpy="0 0 0" />
            <geometry>
                <mesh filename="package://tjurm_arm_final/meshes/link2.STL" />
            </geometry>
            <material name="">
                <color rgba="1 1 1 1" />
            </material>
        </visual>
        <collision>
            <origin xyz="0 0 0" rpy="0 0 0" />
            <geometry>
                <mesh filename="package://tjurm_arm_final/meshes/link2.STL" />
            </geometry>
        </collision>
    </link>
    <joint name="joint2" type="revolute">
        <origin xyz="0 0 0" rpy="-1.5708 0 0" />
        <parent link="link1" />
        <child link="link2" />
        <axis xyz="0 0 1" />
        <limit lower="-3.14" upper="3.14" effort="100" velocity="1" />
    </joint>
    <link name="link3">
        <inertial>
            <origin xyz="0.46285 0.24405 0.010212" rpy="0 0 0" />
            <mass value="33.889" />
            <inertia ixx="0.38228" ixy="-0.12633" ixz="5.6831E-08" iyy="0.43762" iyz="3.695E-07" izz="0.56671" />
        </inertial>
        <visual>
            <origin xyz="0 0 0" rpy="0 0 0" />
            <geometry>
                <mesh filename="package://tjurm_arm_final/meshes/link3.STL" />
            </geometry>
            <material name="">
                <color rgba="1 1 1 1" />
            </material>
        </visual>
        <collision>
            <origin xyz="0 0 0" rpy="0 0 0" />
            <geometry>
                <mesh filename="package://tjurm_arm_final/meshes/link3.STL" />
            </geometry>
        </collision>
    </link>
    <joint name="joint3" type="revolute">
        <origin xyz="0.10898 -0.2795 0" rpy="0 0 -1.5708" />
        <parent link="link2" />
        <child link="link3" />
        <axis xyz="0 0 1" />
        <limit lower="-3.14" upper="3.14" effort="100" velocity="1" />
    </joint>
    <link name="link4">
        <inertial>
            <origin xyz="1.6006E-05 0.0020602 -0.1441" rpy="0 0 0" />
            <mass value="0.67592" />
            <inertia ixx="0.0014386" ixy="8.9402E-08" ixz="1.5146E-07" iyy="0.0014246" iyz="-2.5174E-07" izz="0.00033236" />
        </inertial>
        <visual>
            <origin xyz="0 0 0" rpy="0 0 0" />
            <geometry>
                <mesh filename="package://tjurm_arm_final/meshes/link4.STL" />
            </geometry>
            <material name="">
                <color rgba="1 1 1 1" />
            </material>
        </visual>
        <collision>
            <origin xyz="0 0 0" rpy="0 0 0" />
            <geometry>
                <mesh filename="package://tjurm_arm_final/meshes/link4.STL" />
            </geometry>
        </collision>
    </link>
    <joint name="joint4" type="revolute">
        <origin xyz="0.077079 0.40288 0" rpy="-1.5708 0 -0.0299" />
        <parent link="link3" />
        <child link="link4" />
        <axis xyz="0 0 1" />
        <limit lower="-3.14" upper="3.14" effort="100" velocity="1" />
    </joint>
    <link name="link5">
        <inertial>
            <origin xyz="-0.00082273 -0.029904 0.0019507" rpy="0 0 0" />
            <mass value="0.24703" />
            <inertia ixx="6.3129E-05" ixy="2.0859E-13" ixz="-2.4905E-12" iyy="0.00010174" iyz="2.5079E-14" izz="6.3518E-05" />
        </inertial>
        <visual>
            <origin xyz="0 0 0" rpy="0 0 0" />
            <geometry>
                <mesh filename="package://tjurm_arm_final/meshes/link5.STL" />
            </geometry>
            <material name="">
                <color rgba="0.37255 0.37255 0.37255 1" />
            </material>
        </visual>
        <collision>
            <origin xyz="0 0 0" rpy="0 0 0" />
            <geometry>
                <mesh filename="package://tjurm_arm_final/meshes/link5.STL" />
            </geometry>
        </collision>
    </link>
    <joint name="joint5" type="revolute">
        <origin xyz="0 0 0" rpy="-1.5708 0.16437 0" />
        <parent link="link4" />
        <child link="link5" />
        <axis xyz="0 0 1" />
        <limit lower="-3.14" upper="3.14" effort="100" velocity="1" />
    </joint>
    <link name="link6">
        <inertial>
            <origin xyz="0.0029253 4.8597E-05 0.11575" rpy="0 0 0" />
            <mass value="7.6366" />
            <inertia ixx="0.048445" ixy="-9.6208E-11" ixz="1.3674E-06" iyy="0.048461" iyz="-2.3383E-08" izz="0.048449" />
        </inertial>
        <visual>
            <origin xyz="0 0 0" rpy="0 0 0" />
            <geometry>
                <mesh filename="package://tjurm_arm_final/meshes/link6.STL" />
            </geometry>
            <material name="">
                <color rgba="1 1 1 1" />
            </material>
        </visual>
        <collision>
            <origin xyz="0 0 0" rpy="0 0 0" />
            <geometry>
                <mesh filename="package://tjurm_arm_final/meshes/link6.STL" />
            </geometry>
        </collision>
    </link>
    <joint name="joint6" type="revolute">
        <origin xyz="0 -0.042454 0" rpy="1.5708 0 0" />
        <parent link="link5" />
        <child link="link6" />
        <axis xyz="0 0 1" />
        <limit lower="-3.14" upper="3.14" effort="100" velocity="1" />
    </joint>
    <transmission name="trans_joint1">
        <type>transmission_interface/SimpleTransmission</type>
        <joint name="joint1">
            <hardwareInterface>hardware_interface/EffortJointInterface</hardwareInterface>
        </joint>
        <actuator name="joint1_motor">
            <hardwareInterface>hardware_interface/EffortJointInterface</hardwareInterface>
            <mechanicalReduction>1</mechanicalReduction>
        </actuator>
    </transmission>
    <transmission name="trans_joint2">
        <type>transmission_interface/SimpleTransmission</type>
        <joint name="joint2">
            <hardwareInterface>hardware_interface/EffortJointInterface</hardwareInterface>
        </joint>
        <actuator name="joint2_motor">
            <hardwareInterface>hardware_interface/EffortJointInterface</hardwareInterface>
            <mechanicalReduction>1</mechanicalReduction>
        </actuator>
    </transmission>
    <transmission name="trans_joint3">
        <type>transmission_interface/SimpleTransmission</type>
        <joint name="joint3">
            <hardwareInterface>hardware_interface/EffortJointInterface</hardwareInterface>
        </joint>
        <actuator name="joint3_motor">
            <hardwareInterface>hardware_interface/EffortJointInterface</hardwareInterface>
            <mechanicalReduction>1</mechanicalReduction>
        </actuator>
    </transmission>
    <transmission name="trans_joint4">
        <type>transmission_interface/SimpleTransmission</type>
        <joint name="joint4">
            <hardwareInterface>hardware_interface/EffortJointInterface</hardwareInterface>
        </joint>
        <actuator name="joint4_motor">
            <hardwareInterface>hardware_interface/EffortJointInterface</hardwareInterface>
            <mechanicalReduction>1</mechanicalReduction>
        </actuator>
    </transmission>
    <transmission name="trans_joint5">
        <type>transmission_interface/SimpleTransmission</type>
        <joint name="joint5">
            <hardwareInterface>hardware_interface/EffortJointInterface</hardwareInterface>
        </joint>
        <actuator name="joint5_motor">
            <hardwareInterface>hardware_interface/EffortJointInterface</hardwareInterface>
            <mechanicalReduction>1</mechanicalReduction>
        </actuator>
    </transmission>
    <transmission name="trans_joint6">
        <type>transmission_interface/SimpleTransmission</type>
        <joint name="joint6">
            <hardwareInterface>hardware_interface/EffortJointInterface</hardwareInterface>
        </joint>
        <actuator name="joint6_motor">
            <hardwareInterface>hardware_interface/EffortJointInterface</hardwareInterface>
            <mechanicalReduction>1</mechanicalReduction>
        </actuator>
    </transmission>
    <gazebo>
        <plugin name="gazebo_ros_control" filename="libgazebo_ros_control.so">
            <robotNamespace>/</robotNamespace>
        </plugin>
    </gazebo>
</robot>

